<?xml version='1.0'?>
<sdf version='1.6'>
  <model name='m_4wrobot'>
	  <static>true</static>
	  <pose>0 0 0 0 0 0</pose>
	  <link name = 'chassis'>
		  <pose>0 0 0.1260 0 0 0</pose>
		  
		  <visual name='visual'>
			  <geometry>
				  <cylinder>
					  <radius>0.25</radius>
					  <length>0.01</length>
				  </cylinder>
			  </geometry>
			  
		  </visual>
		  <collision name='collision'>
			  <geometry>
				  <cylinder>
					  <radius>0.25</radius>
					  <length>0.01</length>
				  </cylinder>
			  </geometry>
		  </collision>
	  </link>
	  <link name = 'wheelFL'>
		  <pose>0.0919 0.13485 0.0605 0 1.5705 1.5705</pose>
		  <visual name = 'visual'>
			  <geometry>
				  <cylinder>
					  <radius>0.0605</radius>
					  <length>0.0605</length>
				  </cylinder>
			  </geometry>
			  <material>
				<ambient>0.2 0.2 0.2 01</ambient>
				<diffuse>0.2 0.2 0.2 01</diffuse>
				<specular>0 0 0 0</specular>
				<emissive>0 0 0 0</emissive>
			  </material>
		  </visual>
		  <collision name = 'collision'>
			  <geometry>
				  <cylinder>
					  <radius>0.0605</radius>
					  <length>0.0605</length>
				  </cylinder>
			  </geometry>
		  </collision>
      </link>
      <link name = 'wheelFR'>
		  <pose>0.0919 -0.13485 0.0605 0 1.5705 1.5705</pose>
		  <visual name = 'visual'>
			  <geometry>
				  <cylinder>
					  <radius>0.0605</radius>
					  <length>0.0605</length>
				  </cylinder>
			  </geometry>
			  <material>
				<ambient>0.2 0.2 0.2 01</ambient>
				<diffuse>0.2 0.2 0.2 01</diffuse>
				<specular>0 0 0 0</specular>
				<emissive>0 0 0 0</emissive>
			  </material>
		  </visual>
		  <collision name = 'collision'>
			  <geometry>
				  <cylinder>
					  <radius>0.0605</radius>
					  <length>0.0605</length>
				  </cylinder>
			  </geometry>
		  </collision>
      </link>
      <link name = 'wheelBR'>
		  <pose>-0.0919 -0.13485 0.0605 0 1.5705 1.5705</pose>
		  <visual name = 'visual'>
			  <geometry>
				  <cylinder>
					  <radius>0.0605</radius>
					  <length>0.0605</length>
				  </cylinder>
			  </geometry>
			  <material>
				<ambient>0.2 0.2 0.2 01</ambient>
				<diffuse>0.2 0.2 0.2 01</diffuse>
				<specular>0 0 0 0</specular>
				<emissive>0 0 0 0</emissive>
			  </material>
		  </visual>
		  <collision name = 'collision'>
			  <geometry>
				  <cylinder>
					  <radius>0.0605</radius>
					  <length>0.0605</length>
				  </cylinder>
			  </geometry>
		  </collision>
      </link>
      <link name = 'wheelBL'>
		  <pose>-0.0919 0.13485 0.0605 0 1.5705 1.5705</pose>
		  <visual name = 'visual'>
			  <geometry>
				  <cylinder>
					  <radius>0.0605</radius>
					  <length>0.0605</length>
				  </cylinder>
			  </geometry>
			  <material>
				<ambient>0.2 0.2 0.2 01</ambient>
				<diffuse>0.2 0.2 0.2 01</diffuse>
				<specular>0 0 0 0</specular>
				<emissive>0 0 0 0</emissive>
			  </material>
		  </visual>
		  <collision name = 'collision'>
			  <geometry>
				  <cylinder>
					  <radius>0.0605</radius>
					  <length>0.0605</length>
				  </cylinder>
			  </geometry>
		  </collision>
      </link>
      <joint type='revolute' name='FR_joint'>
		  <pose>0 0 0.03025 0 0 0</pose>
		  <child>wheelFR</child>
		  <parent>chassis</parent>
		  <axis>
			  <xyz>0 0 1</xyz>
		  </axis>
		  <physics>
			  <ode>
				  <max_force>0</max_force>
			  </ode>
		  </physics>
      </joint>
      <joint type='revolute' name='FL_joint'>
		  <pose>0 0 -0.03025 0 0 0</pose>
		  <child>wheelFL</child>
		  <parent>chassis</parent>
		  <axis>
			  <xyz>0 0 1</xyz>
		  </axis>
		  <physics>
			  <ode>
				  <max_force>0</max_force>
			  </ode>
		  </physics>
      </joint>
      <joint type='revolute' name='BR_joint'>
		  <pose>0 0 0.03025 0 0 0</pose>
		  <child>wheelBR</child>
		  <parent>chassis</parent>
		  <axis>
			  <xyz>0 0 1</xyz>
		  </axis>
		  <physics>
			  <ode>
				  <max_force>0</max_force>
			  </ode>
		  </physics>
      </joint>
      <joint type='revolute' name='BL_joint'>
		  <pose>0 0 -0.03025 0 0 0</pose>
		  <child>wheelBL</child>
		  <parent>chassis</parent>
		  <axis>
			  <xyz>0 0 1</xyz>
		  </axis>
		  <physics>
			  <ode>
				  <max_force>0</max_force>
			  </ode>
		  </physics>
      </joint>
      
	  <!--<plugin name='mp_model_push_vel' filename='libmp_model_push_vel2.so'/>-->
  </model>
 </sdf>
