<?xml version='1.0'?>
<sdf version ='1.6'>
  <model name ='m_nest'>
    <pose>0 0 0 0 0 0</pose>
    <static>false</static>
    <link name ='chassis'>
			<pose>0 0 0.3 0 0 0</pose>
	    <inertial>
			<mass>100</mass>
			<inertia>
				<ixx>8.33333333333332</ixx>
				<ixy>0</ixy>
				<ixz>0</ixz>
				<iyy>8.33333333333332</iyy>
				<iyz>0</iyz>
				<izz>8.33333333333332</izz>
			</inertia>
		 </inertial>
     <!-- <pose>0 0 .5 0 0 0</pose> -->
      <collision name ='collision'>
		  <!--<pose>0 0 0 0 0 0</pose>-->
        <geometry>
					<cylinder>
						<radius>0.5</radius>
						<length>0.5</length>
					</cylinder>
							<!--<box>
						<size>0.4 0.4 1</size>
					</box>-->
						</geometry>
					</collision>
					
					<visual name ='visual'>
						<geometry>
					<cylinder>
						<radius>0.5</radius>
						<length>0.5</length>
					</cylinder>
          <!--<box>
			  <size>0.4 0.4 1</size>
		  </box>-->
        </geometry>
				<material>
					<ambient>0.5 0.5 0.5 01</ambient>
					<diffuse>0 0 0 01</diffuse>
					<specular>0 0 0 0</specular>
					<emissive>0 0 0 0</emissive>
				</material>
				<transparency>0</transparency>
      </visual>
    </link>

		<link name = 'wheelL'>
		  <pose>0 0.4 0.0605 0 1.571429 1.571429</pose>
	    <inertial>
			<mass>100</mass>
			<inertia>
				<ixx>0.12200833333333332</ixx>
				<ixy>0</ixy>
				<ixz>0</ixz>
				<iyy>0.12200833333333332</iyy>
				<iyz>0</iyz>
				<izz>0.12200833333333332</izz>
			</inertia>
		 </inertial>
		  <visual name = 'visual'>
			  <geometry>
				  <cylinder>
					  <radius>0.0605</radius>
					  <length>0.0605</length>
				  </cylinder>
			  </geometry>
			  <material>
				<ambient>0.2 0.2 0.2 01</ambient>
				<diffuse>0.2 0.2 0.2 01</diffuse>
				<specular>0 0 0 0</specular>
				<emissive>0 0 0 0</emissive>
			  </material>
		  </visual>
		  <visual name = 'visual1'>
			  <pose>0 0.05 0.03025 0 0 0</pose>
			  <geometry>
				  <cylinder>
					  <radius>0.010083333333333333</radius>
					  <length>0.03025</length>
				  </cylinder>
			  </geometry>
			  <material>
				<ambient>0 0.7 0 01</ambient>
				<diffuse>0 0.7 0 01</diffuse>
				<specular>0 0 0 0</specular>
				<emissive>0 0 0 0</emissive>
			  </material>
		  </visual>
		  
		  <collision name = 'collision'>
			  <geometry>
				  <cylinder>
					  <radius>0.0605</radius>
					  <length>0.0605</length>
				  </cylinder>
			  </geometry>
		  </collision>
      </link>
      

      <link name = 'wheelR'>
		  <pose>0 -0.4 0.0605 0 1.571429 1.571429</pose>
		  <inertial>
		    <mass>100</mass>
			<inertia>
				<ixx>0.12200833333333332</ixx>
				<ixy>0</ixy>
				<ixz>0</ixz>
				<iyy>0.12200833333333332</iyy>
				<iyz>0</iyz>
				<izz>0.12200833333333332</izz>
			</inertia>
		 </inertial>
		  <visual name = 'visual'>
			  <geometry>
				  <cylinder>
					  <radius>0.0605</radius>
					  <length>0.0605</length>
				  </cylinder>
			  </geometry>
			  <material>
				<ambient>0.2 0.2 0.2 01</ambient>
				<diffuse>0.2 0.2 0.2 01</diffuse>
				<specular>0 0 0 0</specular>
				<emissive>0 0 0 0</emissive>
			  </material>
		  </visual>
		  <visual name = 'visual1'>
			  <pose>0 0.05 -0.03025 0 0 0</pose>
			  <geometry>
				  <cylinder>
					  <radius>0.010083333333333333</radius>
					  <length>0.03025</length>
				  </cylinder>
			  </geometry>
			  <material>
				<ambient>0 0.7 0 01</ambient>
				<diffuse>0 0.7 0 01</diffuse>
				<specular>0 0 0 0</specular>
				<emissive>0 0 0 0</emissive>
			  </material>
		  </visual>
		  <collision name = 'collision'>
			  <geometry>
				  <cylinder>
					  <radius>0.0605</radius>
					  <length>0.0605</length>
				  </cylinder>
			  </geometry>
		  </collision>
      </link>
	  <joint type='revolute' name='L_joint'>
				<pose>0 0 -0.03025 0 0 0</pose><!-- -0.03025 -->
				<child>wheelL</child>
				<parent>chassis</parent>
				<axis>
					<xyz>0 0 1</xyz>
				</axis>
				<physics>
					<ode>
						<max_force>0</max_force>
					</ode>
				</physics>
      </joint>
      <joint type='revolute' name='R_joint'>
				<pose>0 0 0.03025 0 0 0</pose>
				<child>wheelR</child>
				<parent>chassis</parent>
				<axis>
					<xyz>0 0 1</xyz>
				</axis>
				<physics>
					<ode>
						<max_force>0</max_force>
					</ode>
				</physics>
      </joint>

      <link name = 'wheelB'>
		  <pose>-0.4 0 0.0605 0 1.571429 1.571429</pose>
		  <inertial>
			<mass>10</mass>
			<inertia>
				<ixx>0.014641000000000003</ixx>
				<ixy>0</ixy>
				<ixz>0</ixz>
				<iyy>0.014641000000000003</iyy>
				<iyz>0</iyz>
				<izz>0.014641000000000003</izz>
			</inertia>
		 </inertial>
		  <visual name = 'visual'>
		  
			  <geometry>
				  <sphere>
					  <radius>0.0605</radius>
				  </sphere>
			  </geometry>
			  <material>
				<ambient>0.2 0.2 0.2 01</ambient>
				<diffuse>0.2 0.2 0.2 01</diffuse>
				<specular>0 0 0 0</specular>
				<emissive>0 0 0 0</emissive>
			  </material>
		  </visual>
		  <collision name = 'collision'>
			  <geometry>
				  <sphere>
					  <radius>0.0605</radius>
				  </sphere>
			  </geometry>
		  </collision>
      </link>
      <joint type='ball' name='B_joint'>
				<child>wheelB</child>
				<parent>chassis</parent>
      </joint>
      
      <link name = 'wheelF'>
		  <pose>0.4 0 0.0605 0 1.571429 1.571429</pose>
		  <inertial>
			<mass>10</mass>
			<inertia>
				<ixx>0.014641000000000003</ixx>
				<ixy>0</ixy>
				<ixz>0</ixz>
				<iyy>0.014641000000000003</iyy>
				<iyz>0</iyz>
				<izz>0.014641000000000003</izz>
			</inertia>
		 </inertial>
		  <visual name = 'visual'>
			  <geometry>
				  <sphere>
					  <radius>0.0605</radius>
				  </sphere>
			  </geometry>
			  <material>
				<ambient>0.2 0.2 0.2 01</ambient>
				<diffuse>0.2 0.2 0.2 01</diffuse>
				<specular>0 0 0 0</specular>
				<emissive>0 0 0 0</emissive>
			  </material>
		  </visual>
		  <collision name = 'collision'>
			  <geometry>
				  <sphere>
					  <radius>0.0605</radius>
				  </sphere>
			  </geometry>
		  </collision>
      </link>
      <joint type='ball' name='F_joint'>
				<child>wheelF</child>
				<parent>chassis</parent>
      </joint>

	<plugin name='nest_plugin' filename='libnest_plugin.so'/>  
  </model>
</sdf>
